[2025-07-25T10:19:41.312+0000] {local_task_job_runner.py:123} INFO - ::group::Pre task execution logs
[2025-07-25T10:19:41.327+0000] {taskinstance.py:2614} INFO - Dependencies all met for dep_context=non-requeueable deps ti=<TaskInstance: etl_to_db.load_to_db scheduled__2025-05-01T00:00:00+00:00 [queued]>
[2025-07-25T10:19:41.336+0000] {taskinstance.py:2614} INFO - Dependencies all met for dep_context=requeueable deps ti=<TaskInstance: etl_to_db.load_to_db scheduled__2025-05-01T00:00:00+00:00 [queued]>
[2025-07-25T10:19:41.337+0000] {taskinstance.py:2867} INFO - Starting attempt 2 of 2
[2025-07-25T10:19:41.352+0000] {taskinstance.py:2890} INFO - Executing <Task(PythonOperator): load_to_db> on 2025-05-01 00:00:00+00:00
[2025-07-25T10:19:41.364+0000] {logging_mixin.py:190} WARNING - /home/airflow/.local/lib/python3.12/site-packages/airflow/task/task_runner/standard_task_runner.py:70 DeprecationWarning: This process (pid=2076) is multi-threaded, use of fork() may lead to deadlocks in the child.
[2025-07-25T10:19:41.367+0000] {standard_task_runner.py:72} INFO - Started process 2086 to run task
[2025-07-25T10:19:41.370+0000] {standard_task_runner.py:104} INFO - Running: ['airflow', 'tasks', 'run', 'etl_to_db', 'load_to_db', 'scheduled__2025-05-01T00:00:00+00:00', '--job-id', '53', '--raw', '--subdir', 'DAGS_FOLDER/etl_to_db.py', '--cfg-path', '/tmp/tmp_oyqkse1']
[2025-07-25T10:19:41.375+0000] {standard_task_runner.py:105} INFO - Job 53: Subtask load_to_db
[2025-07-25T10:19:41.476+0000] {task_command.py:467} INFO - Running <TaskInstance: etl_to_db.load_to_db scheduled__2025-05-01T00:00:00+00:00 [running]> on host 74cfddf97016
[2025-07-25T10:19:41.567+0000] {taskinstance.py:3134} INFO - Exporting env vars: AIRFLOW_CTX_DAG_OWNER='airflow' AIRFLOW_CTX_DAG_ID='etl_to_db' AIRFLOW_CTX_TASK_ID='load_to_db' AIRFLOW_CTX_EXECUTION_DATE='2025-05-01T00:00:00+00:00' AIRFLOW_CTX_TRY_NUMBER='2' AIRFLOW_CTX_DAG_RUN_ID='scheduled__2025-05-01T00:00:00+00:00'
[2025-07-25T10:19:41.569+0000] {taskinstance.py:732} INFO - ::endgroup::
[2025-07-25T10:19:41.619+0000] {logging_mixin.py:190} INFO - Error with row {'region': 'Portugal', 'local_open': '08:00', 'local_close': '16:30'}: can only concatenate list (not "str") to list
[2025-07-25T10:19:41.619+0000] {logging_mixin.py:190} INFO - Error with row {'region': 'United States', 'local_open': '09:30', 'local_close': '16:15'}: can only concatenate list (not "str") to list
[2025-07-25T10:19:41.620+0000] {logging_mixin.py:190} INFO - Error with row {'region': 'Brazil', 'local_open': '10:00', 'local_close': '17:30'}: can only concatenate list (not "str") to list
[2025-07-25T10:19:41.620+0000] {logging_mixin.py:190} INFO - Error with row {'region': 'Canada', 'local_open': '09:30', 'local_close': '16:00'}: can only concatenate list (not "str") to list
[2025-07-25T10:19:41.621+0000] {logging_mixin.py:190} INFO - Error with row {'region': 'South Africa', 'local_open': '09:00', 'local_close': '17:00'}: can only concatenate list (not "str") to list
[2025-07-25T10:19:41.621+0000] {logging_mixin.py:190} INFO - Error with row {'region': 'Spain', 'local_open': '09:00', 'local_close': '17:30'}: can only concatenate list (not "str") to list
[2025-07-25T10:19:41.621+0000] {logging_mixin.py:190} INFO - Error with row {'region': 'Global', 'local_open': '00:00', 'local_close': '23:59'}: can only concatenate list (not "str") to list
[2025-07-25T10:19:41.622+0000] {logging_mixin.py:190} INFO - Error with row {'region': 'Japan', 'local_open': '09:00', 'local_close': '15:00'}: can only concatenate list (not "str") to list
[2025-07-25T10:19:41.622+0000] {logging_mixin.py:190} INFO - Error with row {'region': 'France', 'local_open': '09:00', 'local_close': '17:30'}: can only concatenate list (not "str") to list
[2025-07-25T10:19:41.622+0000] {logging_mixin.py:190} INFO - Error with row {'region': 'Mexico', 'local_open': '08:30', 'local_close': '15:00'}: can only concatenate list (not "str") to list
[2025-07-25T10:19:41.623+0000] {logging_mixin.py:190} INFO - Error with row {'region': 'India', 'local_open': '09:15', 'local_close': '15:30'}: can only concatenate list (not "str") to list
[2025-07-25T10:19:41.623+0000] {logging_mixin.py:190} INFO - Error with row {'region': 'Hong Kong', 'local_open': '09:30', 'local_close': '16:00'}: can only concatenate list (not "str") to list
[2025-07-25T10:19:41.623+0000] {logging_mixin.py:190} INFO - Error with row {'region': 'Mainland China', 'local_open': '09:30', 'local_close': '15:00'}: can only concatenate list (not "str") to list
[2025-07-25T10:19:41.623+0000] {logging_mixin.py:190} INFO - Error with row {'region': 'Germany', 'local_open': '08:00', 'local_close': '20:00'}: can only concatenate list (not "str") to list
[2025-07-25T10:19:41.624+0000] {logging_mixin.py:190} INFO - Error with row {'region': 'United Kingdom', 'local_open': '08:00', 'local_close': '16:30'}: can only concatenate list (not "str") to list
[2025-07-25T10:19:41.624+0000] {logging_mixin.py:190} INFO - 0 row(s) affected in 'regions'
[2025-07-25T10:19:41.650+0000] {taskinstance.py:3313} ERROR - Task failed with exception
Traceback (most recent call last):
  File "/home/airflow/.local/lib/python3.12/site-packages/airflow/models/taskinstance.py", line 768, in _execute_task
    result = _execute_callable(context=context, **execute_callable_kwargs)
             ^^^^^^^^^^^^^^^^^^^^^^^^^^^^^^^^^^^^^^^^^^^^^^^^^^^^^^^^^^^^^
  File "/home/airflow/.local/lib/python3.12/site-packages/airflow/models/taskinstance.py", line 734, in _execute_callable
    return ExecutionCallableRunner(
           ^^^^^^^^^^^^^^^^^^^^^^^^
  File "/home/airflow/.local/lib/python3.12/site-packages/airflow/utils/operator_helpers.py", line 252, in run
    return self.func(*args, **kwargs)
           ^^^^^^^^^^^^^^^^^^^^^^^^^^
  File "/home/airflow/.local/lib/python3.12/site-packages/airflow/models/baseoperator.py", line 424, in wrapper
    return func(self, *args, **kwargs)
           ^^^^^^^^^^^^^^^^^^^^^^^^^^^
  File "/home/airflow/.local/lib/python3.12/site-packages/airflow/operators/python.py", line 238, in execute
    return_value = self.execute_callable()
                   ^^^^^^^^^^^^^^^^^^^^^^^
  File "/home/airflow/.local/lib/python3.12/site-packages/airflow/operators/python.py", line 256, in execute_callable
    return runner.run(*self.op_args, **self.op_kwargs)
           ^^^^^^^^^^^^^^^^^^^^^^^^^^^^^^^^^^^^^^^^^^^
  File "/home/airflow/.local/lib/python3.12/site-packages/airflow/utils/operator_helpers.py", line 252, in run
    return self.func(*args, **kwargs)
           ^^^^^^^^^^^^^^^^^^^^^^^^^^
  File "/opt/airflow/scripts/etl_to_db/load/load_to_db.py", line 130, in load_to_db
    region_map = get_foreign_key_map("regions", ["region"])
                 ^^^^^^^^^^^^^^^^^^^^^^^^^^^^^^^^^^^^^^^^^^
  File "/opt/airflow/scripts/etl_to_db/load/load_to_db.py", line 105, in get_foreign_key_map
    cur.execute(f"SELECT {cols_str} FROM {table_name}")
psycopg2.errors.UndefinedTable: relation "regions" does not exist
LINE 1: SELECT id, region FROM regions
                               ^

[2025-07-25T10:19:41.665+0000] {taskinstance.py:1226} INFO - Marking task as FAILED. dag_id=etl_to_db, task_id=load_to_db, run_id=scheduled__2025-05-01T00:00:00+00:00, execution_date=20250501T000000, start_date=20250725T101941, end_date=20250725T101941
[2025-07-25T10:19:41.688+0000] {taskinstance.py:341} INFO - ::group::Post task execution logs
[2025-07-25T10:19:41.689+0000] {standard_task_runner.py:124} ERROR - Failed to execute job 53 for task load_to_db (relation "regions" does not exist
LINE 1: SELECT id, region FROM regions
                               ^
; 2086)
Traceback (most recent call last):
  File "/home/airflow/.local/lib/python3.12/site-packages/airflow/task/task_runner/standard_task_runner.py", line 117, in _start_by_fork
    ret = args.func(args, dag=self.dag)
          ^^^^^^^^^^^^^^^^^^^^^^^^^^^^^
  File "/home/airflow/.local/lib/python3.12/site-packages/airflow/cli/cli_config.py", line 49, in command
    return func(*args, **kwargs)
           ^^^^^^^^^^^^^^^^^^^^^
  File "/home/airflow/.local/lib/python3.12/site-packages/airflow/utils/cli.py", line 116, in wrapper
    return f(*args, **kwargs)
           ^^^^^^^^^^^^^^^^^^
  File "/home/airflow/.local/lib/python3.12/site-packages/airflow/cli/commands/task_command.py", line 483, in task_run
    task_return_code = _run_task_by_selected_method(args, _dag, ti)
                       ^^^^^^^^^^^^^^^^^^^^^^^^^^^^^^^^^^^^^^^^^^^^
  File "/home/airflow/.local/lib/python3.12/site-packages/airflow/cli/commands/task_command.py", line 256, in _run_task_by_selected_method
    return _run_raw_task(args, ti)
           ^^^^^^^^^^^^^^^^^^^^^^^
  File "/home/airflow/.local/lib/python3.12/site-packages/airflow/cli/commands/task_command.py", line 341, in _run_raw_task
    return ti._run_raw_task(
           ^^^^^^^^^^^^^^^^^
  File "/home/airflow/.local/lib/python3.12/site-packages/airflow/utils/session.py", line 97, in wrapper
    return func(*args, session=session, **kwargs)
           ^^^^^^^^^^^^^^^^^^^^^^^^^^^^^^^^^^^^^^
  File "/home/airflow/.local/lib/python3.12/site-packages/airflow/models/taskinstance.py", line 3006, in _run_raw_task
    return _run_raw_task(
           ^^^^^^^^^^^^^^
  File "/home/airflow/.local/lib/python3.12/site-packages/airflow/models/taskinstance.py", line 274, in _run_raw_task
    TaskInstance._execute_task_with_callbacks(
  File "/home/airflow/.local/lib/python3.12/site-packages/airflow/models/taskinstance.py", line 3161, in _execute_task_with_callbacks
    result = self._execute_task(context, task_orig)
             ^^^^^^^^^^^^^^^^^^^^^^^^^^^^^^^^^^^^^^
  File "/home/airflow/.local/lib/python3.12/site-packages/airflow/models/taskinstance.py", line 3185, in _execute_task
    return _execute_task(self, context, task_orig)
           ^^^^^^^^^^^^^^^^^^^^^^^^^^^^^^^^^^^^^^^
  File "/home/airflow/.local/lib/python3.12/site-packages/airflow/models/taskinstance.py", line 768, in _execute_task
    result = _execute_callable(context=context, **execute_callable_kwargs)
             ^^^^^^^^^^^^^^^^^^^^^^^^^^^^^^^^^^^^^^^^^^^^^^^^^^^^^^^^^^^^^
  File "/home/airflow/.local/lib/python3.12/site-packages/airflow/models/taskinstance.py", line 734, in _execute_callable
    return ExecutionCallableRunner(
           ^^^^^^^^^^^^^^^^^^^^^^^^
  File "/home/airflow/.local/lib/python3.12/site-packages/airflow/utils/operator_helpers.py", line 252, in run
    return self.func(*args, **kwargs)
           ^^^^^^^^^^^^^^^^^^^^^^^^^^
  File "/home/airflow/.local/lib/python3.12/site-packages/airflow/models/baseoperator.py", line 424, in wrapper
    return func(self, *args, **kwargs)
           ^^^^^^^^^^^^^^^^^^^^^^^^^^^
  File "/home/airflow/.local/lib/python3.12/site-packages/airflow/operators/python.py", line 238, in execute
    return_value = self.execute_callable()
                   ^^^^^^^^^^^^^^^^^^^^^^^
  File "/home/airflow/.local/lib/python3.12/site-packages/airflow/operators/python.py", line 256, in execute_callable
    return runner.run(*self.op_args, **self.op_kwargs)
           ^^^^^^^^^^^^^^^^^^^^^^^^^^^^^^^^^^^^^^^^^^^
  File "/home/airflow/.local/lib/python3.12/site-packages/airflow/utils/operator_helpers.py", line 252, in run
    return self.func(*args, **kwargs)
           ^^^^^^^^^^^^^^^^^^^^^^^^^^
  File "/opt/airflow/scripts/etl_to_db/load/load_to_db.py", line 130, in load_to_db
    region_map = get_foreign_key_map("regions", ["region"])
                 ^^^^^^^^^^^^^^^^^^^^^^^^^^^^^^^^^^^^^^^^^^
  File "/opt/airflow/scripts/etl_to_db/load/load_to_db.py", line 105, in get_foreign_key_map
    cur.execute(f"SELECT {cols_str} FROM {table_name}")
psycopg2.errors.UndefinedTable: relation "regions" does not exist
LINE 1: SELECT id, region FROM regions
                               ^

[2025-07-25T10:19:41.708+0000] {local_task_job_runner.py:266} INFO - Task exited with return code 1
[2025-07-25T10:19:41.717+0000] {taskinstance.py:3901} INFO - 0 downstream tasks scheduled from follow-on schedule check
[2025-07-25T10:19:41.718+0000] {local_task_job_runner.py:245} INFO - ::endgroup::
[2025-07-25T10:42:12.962+0000] {local_task_job_runner.py:123} INFO - ::group::Pre task execution logs
[2025-07-25T10:42:12.974+0000] {taskinstance.py:2614} INFO - Dependencies all met for dep_context=non-requeueable deps ti=<TaskInstance: etl_to_db.load_to_db scheduled__2025-05-01T00:00:00+00:00 [queued]>
[2025-07-25T10:42:12.981+0000] {taskinstance.py:2614} INFO - Dependencies all met for dep_context=requeueable deps ti=<TaskInstance: etl_to_db.load_to_db scheduled__2025-05-01T00:00:00+00:00 [queued]>
[2025-07-25T10:42:12.981+0000] {taskinstance.py:2867} INFO - Starting attempt 2 of 2
[2025-07-25T10:42:12.995+0000] {taskinstance.py:2890} INFO - Executing <Task(PythonOperator): load_to_db> on 2025-05-01 00:00:00+00:00
[2025-07-25T10:42:13.002+0000] {standard_task_runner.py:104} INFO - Running: ['airflow', 'tasks', 'run', 'etl_to_db', 'load_to_db', 'scheduled__2025-05-01T00:00:00+00:00', '--job-id', '68', '--raw', '--subdir', 'DAGS_FOLDER/etl_to_db.py', '--cfg-path', '/tmp/tmpzqo903c3']
[2025-07-25T10:42:13.004+0000] {standard_task_runner.py:105} INFO - Job 68: Subtask load_to_db
[2025-07-25T10:42:13.006+0000] {logging_mixin.py:190} WARNING - /home/airflow/.local/lib/python3.12/site-packages/airflow/task/task_runner/standard_task_runner.py:70 DeprecationWarning: This process (pid=2438) is multi-threaded, use of fork() may lead to deadlocks in the child.
[2025-07-25T10:42:13.006+0000] {standard_task_runner.py:72} INFO - Started process 2448 to run task
[2025-07-25T10:42:13.044+0000] {task_command.py:467} INFO - Running <TaskInstance: etl_to_db.load_to_db scheduled__2025-05-01T00:00:00+00:00 [running]> on host 74cfddf97016
[2025-07-25T10:42:13.104+0000] {taskinstance.py:3134} INFO - Exporting env vars: AIRFLOW_CTX_DAG_OWNER='airflow' AIRFLOW_CTX_DAG_ID='etl_to_db' AIRFLOW_CTX_TASK_ID='load_to_db' AIRFLOW_CTX_EXECUTION_DATE='2025-05-01T00:00:00+00:00' AIRFLOW_CTX_TRY_NUMBER='2' AIRFLOW_CTX_DAG_RUN_ID='scheduled__2025-05-01T00:00:00+00:00'
[2025-07-25T10:42:13.105+0000] {taskinstance.py:732} INFO - ::endgroup::
[2025-07-25T10:42:13.138+0000] {logging_mixin.py:190} INFO - 15 row(s) affected in 'regions'
[2025-07-25T10:42:13.173+0000] {logging_mixin.py:190} INFO - 26 row(s) affected in 'exchanges'
[2025-07-25T10:42:13.211+0000] {logging_mixin.py:190} INFO - 0 row(s) affected in 'industries'
[2025-07-25T10:42:13.317+0000] {logging_mixin.py:190} INFO - 0 row(s) affected in 'sic_industries'
[2025-07-25T10:42:23.963+0000] {logging_mixin.py:190} INFO - 23670 row(s) affected in 'companies'
[2025-07-25T10:42:23.969+0000] {python.py:240} INFO - Done. Returned value was: None
[2025-07-25T10:42:23.973+0000] {taskinstance.py:341} INFO - ::group::Post task execution logs
[2025-07-25T10:42:23.973+0000] {taskinstance.py:353} INFO - Marking task as SUCCESS. dag_id=etl_to_db, task_id=load_to_db, run_id=scheduled__2025-05-01T00:00:00+00:00, execution_date=20250501T000000, start_date=20250725T104212, end_date=20250725T104223
[2025-07-25T10:42:24.031+0000] {local_task_job_runner.py:266} INFO - Task exited with return code 0
[2025-07-25T10:42:24.039+0000] {taskinstance.py:3901} INFO - 0 downstream tasks scheduled from follow-on schedule check
[2025-07-25T10:42:24.040+0000] {local_task_job_runner.py:245} INFO - ::endgroup::
